<?xml version="1.0" encoding="utf-8"?>
<!-- =================================================================================== -->
<!-- |    This document was autogenerated by xacro from redcar_multi.xacro             | -->
<!-- |    EDITING THIS FILE BY HAND IS NOT RECOMMENDED                                 | -->
<!-- =================================================================================== -->
<!-- 组合小车底盘与摄像头与雷达 -->
<robot name="redcar">
  <!-- 离地间距 -->
  <!-- point -->
  <link name="base_link">
    <visual>
      <geometry>
        <sphere radius="0.0001"/>
      </geometry>
      <material name="blue">
        <color rgba="0 0 1 1"/>
      </material>
    </visual>
  </link>
  <!-- 底盘 -->
  <link name="car_body">
    <visual>
      <geometry>
        <box size="0.85 0.68 0.55"/>
      </geometry>
      <origin rpy="0 0 0" xyz="0 0 0"/>
      <material name="red">
        <color rgba="1.0 0.0 0.0 0.3"/>
      </material>
    </visual>
  </link>
  <joint name="base_link_car_body" type="fixed">
    <parent link="base_link"/>
    <child link="car_body"/>
    <origin xyz="0 0 0.375"/>
  </joint>
  <link name="base_l_wheel">
    <visual>
      <geometry>
        <cylinder length="0.12" radius="0.1"/>
      </geometry>
      <origin rpy="1.5705 0.0 0.0" xyz="0.0 0.0 0.0"/>
      <material name="black">
        <color rgba="0 0 0 1"/>
      </material>
    </visual>
  </link>
  <joint name="base_l_wheel_joint" type="continuous">
    <parent link="car_body"/>
    <child link="base_l_wheel"/>
    <origin xyz="-0.175 0.34 -0.275"/>
    <axis xyz="0 1 0"/>
  </joint>
  <link name="base_r_wheel">
    <visual>
      <geometry>
        <cylinder length="0.12" radius="0.1"/>
      </geometry>
      <origin rpy="1.5705 0.0 0.0" xyz="0.0 0.0 0.0"/>
      <material name="black">
        <color rgba="0 0 0 1"/>
      </material>
    </visual>
  </link>
  <joint name="base_r_wheel_joint" type="continuous">
    <parent link="car_body"/>
    <child link="base_r_wheel"/>
    <origin xyz="-0.175 -0.34 -0.275"/>
    <axis xyz="0 1 0"/>
  </joint>
  <!-- 支撑轮半径 -->
  <link name="front_wheel">
    <visual>
      <geometry>
        <sphere radius="0.1"/>
      </geometry>
      <origin rpy="0 0 0" xyz="0 0 0"/>
      <material name="black">
        <color rgba="0 0 0 1"/>
      </material>
    </visual>
  </link>
  <joint name="front_wheel2car_body" type="continuous">
    <parent link="car_body"/>
    <child link="front_wheel"/>
    <origin rpy="0 0 0" xyz="0.325 0 -0.275"/>
    <axis xyz="1 1 1"/>
  </joint>
  <!-- 支架安装的z坐标:底盘高度 / 2 + 支架高度 / 2  -->
  <link name="support_laser">
    <visual>
      <geometry>
        <box size="0.06 0.06 0.06"/>
      </geometry>
      <origin rpy="0.0 0.0 0.0" xyz="0.0 0.0 0.0"/>
      <material name="blue">
        <color rgba="0 0 1 1"/>
      </material>
    </visual>
  </link>
  <joint name="support2car_body" type="fixed">
    <parent link="car_body"/>
    <child link="support_laser"/>
    <origin xyz="-0.375 0.0 0.305"/>
  </joint>
  <!-- 雷达安装的z坐标:支架高度 / 2 + 雷达高度 / 2  -->
  <!-- 雷达关节以及link -->
  <link name="laser">
    <visual>
      <geometry>
        <cylinder length="0.042" radius="0.02"/>
      </geometry>
      <origin rpy="0.0 0.0 0.0" xyz="0.0 0.0 0.0"/>
      <material name="black"/>
    </visual>
  </link>
  <joint name="laser2support" type="fixed">
    <parent link="support_laser"/>
    <child link="laser"/>
    <origin xyz="0 0.0 0.051"/>
  </joint>
  <!-- 摄像头安装的z坐标:底盘高度 / 2 + 摄像头高度 / 2  -->
  <!-- 摄像头关节以及link -->
  <link name="imu_link">
    <visual>
      <geometry>
        <box size="0.03 0.04 0.01"/>
      </geometry>
      <origin rpy="0.0 0.0 0.0" xyz="0.0 0.0 0.0"/>
      <material name="green">
        <color rgba="0 1 0 1"/>
      </material>
    </visual>
  </link>
  <joint name="camera2base_link" type="fixed">
    <parent link="car_body"/>
    <child link="imu_link"/>
    <origin xyz="-0.375 0.3 0.28"/>
  </joint>
</robot>

